
exception Exception__;
exception Ex;
println(Exception__);

func test2() {
    println("Hello World");
}

print([1,2,3,4,5][2000]);
func test1(x) {
    try {
        #test2(123123, 122321, x);
        raise Exception__("Hello World");
        raise Exception__();
    } catch (Exception__()) {
        print("Exception__");
        print(1/0);
    }
}

func a() {
    func b() {
        func c() {
            test1(2);
        }
        c();
    }
    b();
}
a();