
exception Exception__;
exception Ex;
println(Exception__);

func test2() {
    println("Hello World");
}

func test1(x) {
    try {
        raise Ex("hello");
    } catch (Exception__()) {
        print("Exception__");
    }
}

func a() {
    func b() {
        func c() {
            test1(2, 2);
        }
        c();
    }
    b();
}
a();