
exception z;
exception Ex;
println(z);

func test2() {
    println("Hello World");
}

func test1(x) {
    try {
        test2(123123, 122321, x);
        raise z();
    } catch (z()) {
        print("z");
    }
}

func a() {
    func b() {
        func c() {
            test1();
        }
        c();
    }
    b();
}
a();